<?xml version="1.0" ?>
<!-- =================================================================================== -->
<!-- |    This document was autogenerated by xacro from inmoov_shadow_hand_v2.urdf.xacro | -->
<!-- |    EDITING THIS FILE BY HAND IS NOT RECOMMENDED                                 | -->
<!-- =================================================================================== -->
<robot name="inmoov">
  <!--xacro:property name="pi" value="3.1415926539"/-->
  <!-- meshlab steps taken from http://gazebosim.org/tutorials?tut=inertia -->
  <!-- assume material density is 1.0g per 1.0cm^2 -->
  <!-- ABS is 1.04g per 1.0cm^3 -->
  <!-- PLA is 1.25g per 1.0cm^3 -->
  <!-- <xacro:include filename="$(find inmoov_description)/urdf/inmoov.gazebo" /> -->
  <!-- usage: e.g. ${M_PI/4} -->
  <material name="Blue">
    <color rgba="0.0 0.0 0.8 1.0"/>
  </material>
  <material name="Green">
    <color rgba="0.0 0.8 0.0 1.0"/>
  </material>
  <material name="BiotacGreen">
    <color rgba="0.31 0.85 0.42 1.0"/>
  </material>
  <material name="Grey">
    <color rgba="0.2 0.2 0.2 1.0"/>
  </material>
  <material name="LightGrey">
    <color rgba="0.6 0.6 0.6 1.0"/>
  </material>
  <material name="Red">
    <color rgba="0.8 0.0 0.0 1.0"/>
  </material>
  <material name="White">
    <color rgba="1.0 1.0 1.0 1.0"/>
  </material>

  <link name="r_shoulder_link">
    <visual>
      <geometry>
        <mesh filename="package://inmoov_meshes/meshes/r_shoulder.stl" scale="0.001 0.001 0.001"/>
      </geometry>
      <origin rpy="0 0 0" xyz="0 0 0"/>
      <material name="cframe">
        <color rgba="0.40 0.40 0.40 1"/>
      </material>
    </visual>
    <inertial>
      <mass value="322.44334375"/>
      <inertia ixx="0.60134592" ixy="0.00343772975" ixz="-0.011761917" iyy="0.473865856" iyz="-0.114277" izz="0.500951584"/>
    </inertial>
  </link>
  <link name="r_bicep_link_aux_0">
    <inertial>
      <origin rpy="0 0 0" xyz="0 0 0"/>
      <mass value="1"/>
      <inertia ixx="0.01" ixy="0" ixz="0" iyy="0.01" iyz="0" izz="0.01"/>
    </inertial>
  </link>
  <link name="r_bicep_link_aux_1">
    <inertial>
      <origin rpy="0 0 0" xyz="0 0 0"/>
      <mass value="1"/>
      <inertia ixx="0.01" ixy="0" ixz="0" iyy="0.01" iyz="0" izz="0.01"/>
    </inertial>
  </link>
  <link name="r_bicep_link">
    <visual>
      <geometry>
        <mesh filename="package://inmoov_meshes/meshes/bicep.stl" scale="0.001 0.001 0.001"/>
      </geometry>
      <origin rpy="0 0 0" xyz="0 0 0"/>
      <material name="cframe">
        <color rgba="0.40 0.40 0.40 1"/>
      </material>
    </visual>
    <inertial>
      <mass value="281.91265625"/>
      <inertia ixx="1.283355392" ixy="-0.000200782203125" ixz="-0.224559104" iyy="1.399255168" iyz="0.0006545236875" izz="0.416621216"/>
    </inertial>
  </link>
  <link name="r_forearm_link_aux">
    <inertial>
      <origin rpy="0 0 0" xyz="0 0 0"/>
      <mass value="1"/>
      <inertia ixx="0.01" ixy="0" ixz="0" iyy="0.01" iyz="0" izz="0.01"/>
    </inertial>
  </link>
  <link name="r_forearm_link">
<!--    openrave cannot visualize primitive shape e.g. box-->
    <visual>
      <geometry>
        <mesh filename="package://inmoov_meshes/meshes/box-binary.stl" scale="0.07 0.07 0.2"/>
      </geometry>
      <origin rpy="0 0 0" xyz="0.03 -0.00 -0.18"/>
    </visual>
    <collision>
      <geometry>
        <box size="0.07 0.07 0.2"/>
      </geometry>
      <origin rpy="0 0 0" xyz="0.03 -0.00 -0.18"/>
    </collision>
    <inertial>
      <mass value="401.76659375"/>
      <inertia ixx="3.242307584" ixy="0.050011216" ixz="-0.14318512" iyy="3.24251008" iyz="0.086288976" izz="0.58458784"/>
    </inertial>
  </link>

  <joint name="r_shoulder_out_joint" type="revolute">
    <axis xyz="1 0 0"/>
    <limit effort="1000.0" lower="-2.07079632679" upper="1.57079632679" velocity="1745.32925199"/>
    <origin rpy="0 0 0" xyz="0 -0.066 -0.06"/>
    <parent link="r_shoulder_link"/>
    <child link="r_bicep_link_aux_0"/>
  </joint>
  <joint name="r_shoulder_lift_joint" type="revolute">
    <axis xyz="0 1 0"/>
    <limit effort="1000.0" lower="-2.07079632679" upper="1.57079632679" velocity="1745.32925199"/>
    <origin rpy="0 0 0" xyz="0 0 0"/>
    <parent link="r_bicep_link_aux_0"/>
    <child link="r_bicep_link_aux_1"/>
  </joint>
  <joint name="r_upper_arm_roll_joint" type="revolute">
    <axis xyz="0 0 1"/>
    <limit effort="1000.0" lower="-1.57079632679" upper="1.57079632679" velocity="1745.32925199"/>
    <origin rpy="0 0 0" xyz="0 0 0"/>
    <parent link="r_bicep_link_aux_1"/>
    <child link="r_bicep_link"/>
  </joint>
  <joint name="r_elbow_flex_joint" type="revolute">
    <axis xyz="0 1 0"/>
    <limit effort="1000.0" lower="-3.14159265359" upper="0.0" velocity="1745.32925199"/>
    <origin rpy="0 0 0" xyz="-0.054 -0.009 -0.2621"/>
    <parent link="r_bicep_link"/>
    <child link="r_forearm_link_aux"/>
  </joint>
  <joint name="r_elbow_roll_joint" type="revolute">
    <axis xyz="0 0 1"/>
    <limit effort="1000.0" lower="-1.57079632679" upper="1.57079632679" velocity="1745.32925199"/>
    <origin rpy="0 0 0" xyz="0.0 0 0.0"/>
    <parent link="r_forearm_link_aux"/>
    <child link="r_forearm_link"/>
  </joint>

  <!-- shadow hand -->
  <link name="r_hand_link">
    <inertial>
      <origin rpy="0 0 0" xyz="0 0 0"/>
      <mass value="1"/>
      <inertia ixx="0.01" ixy="0" ixz="0" iyy="0.01" iyz="0" izz="0.01"/>
    </inertial>
  </link>
  <joint name="r_wrist_roll_joint" type="fixed">
    <parent link="r_forearm_link"/>
    <child link="r_hand_link"/>
    <origin rpy="3.14159265359 0 0" xyz="0.0303 -0.00729 -0.302"/>
  </joint>
  <link name="rh_wrist">
  <!--match mass to arm-->
    <inertial>
      <origin rpy="0 0 0" xyz="0 0 0.029"/>
      <mass value="100"/>
      <inertia ixx="0.035" ixy="0.0" ixz="0.0" iyy="0.064" iyz="0.0" izz="0.0438"/>
    </inertial>
    <visual>
      <origin rpy="0 0 0" xyz="0 0 0"/>
      <geometry name="rh_wrist_visual">
        <mesh filename="package://sr_description/hand/model/wrist.dae" scale="0.001 0.001 0.001"/>
      </geometry>
      <material name="LightGrey"/>
    </visual>
<!--    <collision>-->
<!--      <origin rpy="1.5708 1.5708 0" xyz="0 0 0"/>-->
<!--      <geometry name="rh_wrist_collision_geom">-->
<!--        <cylinder length="0.030" radius="0.0135"/>-->
<!--      </geometry>-->
<!--    </collision>-->
<!--    <collision>-->
<!--      <origin rpy="0 1.5708 0" xyz="-0.026 0 0.034"/>-->
<!--      <geometry>-->
<!--        <cylinder length="0.010" radius="0.011"/>-->
<!--      </geometry>-->
<!--    </collision>-->
<!--    <collision>-->
<!--      <origin rpy="0 1.5708 0" xyz="0.031 0 0.034"/>-->
<!--      <geometry>-->
<!--        <cylinder length="0.010" radius="0.011"/>-->
<!--      </geometry>-->
<!--    </collision>-->
<!--    <collision>-->
<!--      <origin rpy="0 0.7854 0" xyz="-0.021 0 0.011"/>-->
<!--      <geometry>-->
<!--        <box size="0.027 0.018 0.010"/>-->
<!--      </geometry>-->
<!--    </collision>-->
<!--    <collision>-->
<!--      <origin rpy="0 -0.7854 0" xyz="0.026 0 0.010"/>-->
<!--      <geometry>-->
<!--        <box size="0.027 0.018 0.010"/>-->
<!--      </geometry>-->
<!--    </collision>-->
  </link>
  <gazebo reference="rh_wrist">
    <material>Gazebo/White</material>
    <selfCollide>false</selfCollide>
  </gazebo>
  <joint name="rh_WRJ2" type="revolute">
    <parent link="r_hand_link"/>
    <child link="rh_wrist"/>
    <origin rpy="0 0 0" xyz="0 0.0 0.0"/>
    <!-- this is the wrist adduction -->
    <axis xyz="0 1.0 0"/>
    <limit effort="10" lower="-1.0471975512" upper="1.0471975512" velocity="20.0"/>
    <dynamics damping="0.1"/>
  </joint>
  <gazebo reference="rh_WRJ2">
    <provideFeedback>1</provideFeedback>
    <implicitSpringDamper>1</implicitSpringDamper>
  </gazebo>
  <transmission name="rh_wrist_transmission">
    <type>sr_mechanism_model/SimpleTransmission</type>
    <actuator name="rh_WRJ2">
      <mechanicalReduction>1</mechanicalReduction>
    </actuator>
    <joint name="rh_WRJ2">
      <hardwareInterface>EffortJointInterface</hardwareInterface>
      <hardwareInterface>PositionJointInterface</hardwareInterface>
    </joint>
  </transmission>

  <link name="rh_palm">
    <inertial>
      <origin rpy="0 0 0" xyz="0 0 0.035"/>
      <mass value="0.3"/>
      <inertia ixx="0.0003581" ixy="0.0" ixz="0.0" iyy="0.0005287" iyz="0.0" izz="0.000191"/>
    </inertial>
    <!--    openrave cannot visualize primitive shape e.g. box-->
    <visual>
      <geometry>
        <mesh filename="package://inmoov_meshes/meshes/box-binary.stl" scale="0.18 0.15 0.18"/>
      </geometry>
      <origin rpy="0 0 0" xyz="0.05 -0.06 0.1"/>
    </visual>
    <collision>
      <geometry>
        <box size="0.18 0.15 0.18"/>
      </geometry>
      <origin rpy="0 0 0" xyz="0.05 -0.06 0.1"/>
    </collision>
  </link>
  <joint name="rh_WRJ1" type="revolute">
    <parent link="rh_wrist"/>
    <child link="rh_palm"/>
    <origin rpy="0 0 0" xyz="0 0 0.03"/>
    <axis xyz="1 0 0"/>
    <!-- this is the wrist flexion -->
    <limit effort="30" lower="-1.57079632679" upper="1.57079632679" velocity="20.0"/>
    <dynamics damping="0.1"/>
  </joint>
</robot>
